Workbook

Sheet Sensitivity Report 1
A1: Microsoft Excel 16.106 Sensitivity Report
A2: Worksheet: [EfesData.xlsx]Current
A3: Report Created: 2/12/26 3:46:24 PM
A6: Variable Cells
D7: Final | E7: Reduced | F7: Objective | G7: Allowable | H7: Allowable
B8: Cell | C8: Name | D8: Value | E8: Cost | F8: Coefficient | G8: Increase | H8: Decrease
B9: $C$43 | C9: Afyon Istanbul | D9: 29.04 | E9: 0 | F9: 0.0264374 | G9: 0.0026438 | H9: 0.00082242857
B10: $D$43 | C10: Afyon Ankara | D10: 0.96 | E10: 0 | F10: 0.0166864 | G10: 4.9e-05 | H10: 0.0026438
B11: $C$44 | C11: Konya Istanbul | D11: 0 | E11: 0.010339 | F11: 0.0368254 | G11: 1e+30 | H11: 0.010339
B12: $D$44 | C12: Konya Ankara | D12: 25.44 | E12: 0 | F12: 0.0167354 | G12: 0.0026438 | H12: 4.9e-05
B13: $C$45 | C13: Import Istanbul | D13: 0 | E13: 0.0028841455 | F13: 0.0317784 | G13: 1e+30 | H13: 0.0028841455
B14: $D$45 | C14: Import Ankara | D14: 0 | E14: 0.0142566 | F14: 0.0325134 | G14: 1e+30 | H14: 0.0142566
B15: $C$51 | C15: Istanbul Istanbul | D15: 103 | E15: 0 | F15: 0 | G15: 0.031285714 | H15: 1e+30
B16: $D$51 | C16: Istanbul Izmir | D16: 74 | E16: 0 | F16: 0.040357143 | G16: 4.1865321e-17 | H16: 1e+30
B17: $E$51 | C17: Istanbul Antalya | D17: 0 | E17: 0.013857143 | F17: 0.051714286 | G17: 1e+30 | H17: 0.013857143
B18: $F$51 | C18: Istanbul Bursa | D18: 60 | E18: 0 | F18: 0.017357143 | G18: 0.0088571429 | H18: 1e+30
B19: $G$51 | C19: Istanbul Kayseri | D19: 0 | E19: 0.033428571 | F19: 0.055142857 | G19: 1e+30 | H19: 0.033428571
B20: $H$51 | C20: Istanbul Samsun | D20: 0 | E20: 0.025071429 | F20: 0.053 | G20: 1e+30 | H20: 0.025071429
... B28: $I$52 | C28: Ankara Export (Izmir) | D28: 8 | E28: 0 | F28: 0.042928571 | G28: 4.1865321e-17 | H28: 0.013857143
A30: Constraints
D31: Final | E31: Shadow | F31: Constraint | G31: Allowable | H31: Allowable
B32: Cell | C32: Name | D32: Value | E32: Price | F32: R.H. Side | G32: Increase | H32: Decrease
B33: $C$47 | C33: Total beer Istanbul | D33: 242 | E33: 0.003178368 | F33: 0 | G33: 8 | H33: 212
B34: $D$47 | C34: Total beer Ankara | D34: 220 | E34: 0.002008248 | F34: 0 | G34: 354.66667 | H34: 212
B35: $C$53 | C35: Total Istanbul | D35: 103 | E35: 0.003178368 | F35: 103 | G35: 8 | H35: 103 | I35: =G35*E35 -> 0.025426944 | J35: =-H35*E35 -> -0.3273719
B36: $D$53 | C36: Total Izmir | D36: 74 | E36: 0.043535511 | F36: 74 | G36: 8 | H36: 74 | I36: =G36*E36 -> 0.34828409 | J36: =-H36*E36 -> -3.2216278
B37: $E$53 | C37: Total Antalya | D37: 50 | E37: 0.041035511 | F37: 50 | G37: 8 | H37: 5 | I37: =G37*E37 -> 0.32828409 | J37: =-H37*E37 -> -0.20517755
B38: $F$53 | C38: Total Bursa | D38: 60 | E38: 0.020535511 | F38: 60 | G38: 8 | H38: 60 | I38: =G38*E38 -> 0.16428409 | J38: =-H38*E38 -> -1.2321307
B39: $G$53 | C39: Total Kayseri | D39: 102 | E39: 0.024892654 | F39: 102 | G39: 8 | H39: 5 | I39: =G39*E39 -> 0.19914123 | J39: =-H39*E39 -> -0.12446327
B40: $H$53 | C40: Total Samsun | D40: 60 | E40: 0.031106939 | F40: 60 | G40: 8 | H40: 5 | I40: =G40*E40 -> 0.24885552 | J40: =-H40*E40 -> -0.1555347
B41: $I$53 | C41: Total Export (Izmir) | D41: 13 | E41: 0.045035511 | F41: 13 | G41: 8 | H41: 5 | I41: =G41*E41 -> 0.36028409 | J41: =-H41*E41 -> -0.22517755
B42: $E$43 | C42: Afyon Total | D42: 30 | E42: -4.9e-05 | F42: 30 | G42: 25.44 | H42: 0.96
B43: $E$44 | C43: Konya Total | D43: 25.44 | E43: 0 | F43: 68 | G43: 1e+30 | H43: 42.56
B44: $E$45 | C44: Import Total | D44: 0 | E44: 0 | F44: 20 | G44: 1e+30 | H44: 20
B45: $J$51 | C45: Istanbul Total | D45: 242 | E45: 0 | F45: 250 | G45: 1e+30 | H45: 8
B46: $J$52 | C46: Ankara Total | D46: 220 | E46: -9.8691429e-05 | F46: 220 | G46: 5 | H46: 8

Sheet Sensitivity Report 2
A1: Microsoft Excel 16.0 Sensitivity Report
A2: Worksheet: [EfesData_with_LongTermModel.xlsx]Current
A3: Report Created: 2/15/2026 10:32:07 PM
A6: Variable Cells
D7: Final | E7: Reduced | F7: Objective | G7: Allowable | H7: Allowable
B8: Cell | C8: Name | D8: Value | E8: Cost | F8: Coefficient | G8: Increase | H8: Decrease
B9: $C$43 | C9: Afyon Istanbul | D9: 29.04 | E9: 0 | F9: 0.0264374 | G9: 0.0026438 | H9: 0.00082242857
B10: $D$43 | C10: Afyon Ankara | D10: 0.96 | E10: 0 | F10: 0.0166864 | G10: 4.9e-05 | H10: 0.0026438
B11: $C$44 | C11: Konya Istanbul | D11: 0 | E11: 0.010339 | F11: 0.0368254 | G11: 1e+30 | H11: 0.010339
B12: $D$44 | C12: Konya Ankara | D12: 25.44 | E12: 0 | F12: 0.0167354 | G12: 0.0026438 | H12: 4.9e-05
B13: $C$45 | C13: Import Istanbul | D13: 0 | E13: 0.0028841455 | F13: 0.0317784 | G13: 1e+30 | H13: 0.0028841455
B14: $D$45 | C14: Import Ankara | D14: 0 | E14: 0.0142566 | F14: 0.0325134 | G14: 1e+30 | H14: 0.0142566
B15: $C$51 | C15: Istanbul Istanbul | D15: 103 | E15: 0 | F15: 0 | G15: 0.031285714 | H15: 1e+30
B16: $D$51 | C16: Istanbul Izmir | D16: 74 | E16: 0 | F16: 0.040357143 | G16: 1.5612511e-17 | H16: 1e+30
B17: $E$51 | C17: Istanbul Antalya | D17: 0 | E17: 0.013857143 | F17: 0.051714286 | G17: 1e+30 | H17: 0.013857143
B18: $F$51 | C18: Istanbul Bursa | D18: 60 | E18: 0 | F18: 0.017357143 | G18: 0.0088571429 | H18: 1e+30
B19: $G$51 | C19: Istanbul Kayseri | D19: 0 | E19: 0.033428571 | F19: 0.055142857 | G19: 1e+30 | H19: 0.033428571
B20: $H$51 | C20: Istanbul Samsun | D20: 0 | E20: 0.025071429 | F20: 0.053 | G20: 1e+30 | H20: 0.025071429
... B28: $I$52 | C28: Ankara Export (Izmir) | D28: 8 | E28: 0 | F28: 0.042928571 | G28: 1.5612511e-17 | H28: 0.013857143
A30: Constraints
D31: Final | E31: Shadow | F31: Constraint | G31: Allowable | H31: Allowable
B32: Cell | C32: Name | D32: Value | E32: Price | F32: R.H. Side | G32: Increase | H32: Decrease
B33: $C$47 | C33: Total beer Istanbul | D33: 242 | E33: 0.003178368 | F33: 0 | G33: 8 | H33: 212
B34: $D$47 | C34: Total beer Ankara | D34: 220 | E34: 0.002008248 | F34: 0 | G34: 354.66667 | H34: 212
B35: $C$53 | C35: Total Istanbul | D35: 103 | E35: 0.003178368 | F35: 103 | G35: 8 | H35: 103
B36: $D$53 | C36: Total Izmir | D36: 74 | E36: 0.043535511 | F36: 74 | G36: 8 | H36: 74
B37: $E$53 | C37: Total Antalya | D37: 50 | E37: 0.041035511 | F37: 50 | G37: 8 | H37: 5
B38: $F$53 | C38: Total Bursa | D38: 60 | E38: 0.020535511 | F38: 60 | G38: 8 | H38: 60
B39: $G$53 | C39: Total Kayseri | D39: 102 | E39: 0.024892654 | F39: 102 | G39: 8 | H39: 5
B40: $H$53 | C40: Total Samsun | D40: 60 | E40: 0.031106939 | F40: 60 | G40: 8 | H40: 5
B41: $I$53 | C41: Total Export (Izmir) | D41: 13 | E41: 0.045035511 | F41: 13 | G41: 8 | H41: 5
B42: $E$43 | C42: Afyon Total | D42: 30 | E42: -4.9e-05 | F42: 30 | G42: 25.44 | H42: 0.96
B43: $E$44 | C43: Konya Total | D43: 25.44 | E43: 0 | F43: 68 | G43: 1e+30 | H43: 42.56
B44: $E$45 | C44: Import Total | D44: 0 | E44: 0 | F44: 20 | G44: 1e+30 | H44: 20
... B46: $J$52 | C46: Ankara Total | D46: 220 | E46: -9.8691429e-05 | F46: 220 | G46: 5 | H46: 8

Sheet Current
B1: Current year data and shipment plan.
B3: CURRENT DEMAND:
B5: Annual demand at distribution centers
C6: (Million litres/year)
B7: Dist. Centers | C7: Demand
B8: Istanbul | C8: 103
B9: Izmir | C9: 74
B10: Antalya | C10: 50
B11: Bursa | C11: 60
B12: Kayseri | C12: 102
B13: Samsun | C13: 60
B14: Export(Izmir) | C14: 13
B15: Total | C15: =SUM(C8:C14) -> 462
L17: CAPACITY:
B18: TRANSPORTATION COSTS:
L19: Annual capacity of malt plants | O19: Annual capacity of breweries
B20: Annual cost of shipping 1 ton of malt from plant i to brewery j | M20: (1000 tons/year) | R20: (Million litres/year)
B21: (Million $ /1000 ton)* | L21: Afyon | M21: 30 | O21: Existing Breweries | R21: Current
C22: Existing Brewery Sites | L22: Konya | M22: 68 | Q22: Istanbul | R22: 250
B23: Malt Plants | C23: Istanbul | D23: Ankara | L23: Import (Izmir) | M23: 20 | Q23: Ankara | R23: 220
B24: Afyon | C24: 0.0264374 | D24: 0.0166864
B25: Konya | C25: 0.0368254 | D25: 0.0167354
B26: Import (Izmir) | C26: 0.0317784 | D26: 0.0325134
M27: MALT YIELD:
B28: * Tons are metric tons in all measurements.
B30: Annual cost of shipping 1 million liters of beer from brewery j to distribution center k | M30: Million lts beer brewed from
B31: (Million $/Million ltr) | M31: 1000 tons of malt
D32: Distribution Centers | M32: Domestic | N32: 8.3333333
C33: Breweries | D33: Istanbul | E33: Izmir | F33: Antalya | G33: Bursa | H33: Kayseri | I33: Samsun | J33: Export (Izmir) | M33: Import | N33: 9.0909091
C34: Istanbul | D34: 0 | E34: 0.040357143 | F34: 0.051714286 | G34: 0.017357143 | H34: 0.055142857 | I34: 0.053 | J34: 0.041857143
C35: Ankara | D35: 0.032357143 | E35: 0.041428571 | F35: 0.038928571 | G35: 0.027285714 | H35: 0.022785714 | I35: 0.029 | J35: 0.042928571
B39: Current Shipment Plan
B41: Amount of malt shipped from plant i to brewery j in year 1 (1000 ton)
C42: Istanbul | D42: Ankara | E42: Total | F42: Capacity
B43: Afyon | C43: 29.04 | D43: 0.96 | E43: =SUM(C43:D43) -> 30 | F43: 30
B44: Konya | C44: 0 | D44: 25.44 | E44: =SUM(C44:D44) -> 25.44 | F44: 68
B45: Import | C45: 0 | D45: 0 | E45: =SUM(C45:D45) -> 0 | F45: 20
B46: Total malt | C46: =SUM(C43:C45) -> 29.04 | D46: =SUM(D43:D45) -> 26.4
B47: Total beer | C47: =(SUM(C43:C44)*$N$32)+C45*$N$33 -> 242 | D47: =(SUM(D43:D44)*$N$32)+D45*$N$33 -> 220 | E47: (Million lt)
B49: Amount of beer shipped from brewery j to distribution center k in year 1 (Million liters)
...

Sheet LongTermData
B1: Long term demand, potential brewery sites, capacities, yearly equivalent investment costs, and unit transporation costs.
B3: TRANSPORTATION COSTS: | L3: CAPACITY:
B5: Annual cost of shipping 1 ton of malt from plant i to brewery j | L5: Annual capacity of malt plants | P5: Annual capacity of breweries
B6: (Million $ /1000 ton) | D6: Destinations | M6: (1000 tons/year) | S6: (Million litres/year)
C7: Existing Brewery Sites | E7: Potential Brewery Sites | L7: Afyon | M7: 30 | P7: Existing Breweries | S7: Current
B8: Malt Plants | C8: Istanbul | D8: Ankara | E8: Izmir | F8: Sakarya | G8: Adana | H8: Samsun | I8: IstNew | J8: AnkNew | L8: Konya | M8: 68 | R8: Istanbul | S8: 250
B9: Afyon | C9: 0.0264374 | D9: 0.0166864 | E9: 0.0199204 | F9: 0.0191854 | G9: 0.0321704 | H9: 0.037 | I9: 0.0264374 | J9: 0.0166864 | L9: Import (Izmir) | M9: 20 | R9: Ankara | S9: 220
B10: Konya | C10: 0.0368254 | D10: 0.0167354 | E10: 0.0308474 | F10: 0.0295734 | G10: 0.0215374 | H10: 0.033 | I10: 0.0368254 | J10: 0.0167354 | P10: Potential Breweries | S10: New | T10: Expansion
B11: Import (Izmir) | C11: 0.0317784 | D11: 0.0325134 | E11: 0.0040934 | F11: 0.0276134 | G11: 0.0479974 | H11: 0.053 | I11: 0.0317784 | J11: 0.0325134 | R11: Izmir | S11: 90 | T11: 30
L12: MALT YIELD: | R12: Sakarya | S12: 90 | T12: 30
R13: Adana | S13: 90 | T13: 30
B14: Annual cost of shipping 1 million liters of beer from brewery j to distribution center k | R14: Samsun | S14: 90 | T14: 30
B15: (Million $/Million ltr) | L15: Million lts beer brewed from | R15: IstNew | S15: 90 | T15: 30
D16: Distribution Centers | L16: 1000 tons of malt | R16: AnkNew | S16: 90 | T16: 30
C17: Breweries | D17: Istanbul | E17: Izmir | F17: Antalya | G17: Bursa | H17: Kayseri | I17: Samsun | J17: Export (Izmir) | L17: Domestic | M17: 8.3333333
B18: Existing | C18: Istanbul | D18: 0 | E18: 0.040357143 | F18: 0.051714286 | G18: 0.017357143 | H18: 0.055142857 | I18: 0.053 | J18: 0.041857143 | L18: Import | M18: 9.0909091
C19: Ankara | D19: 0.032357143 | E19: 0.041428571 | F19: 0.038928571 | G19: 0.027285714 | H19: 0.022785714 | I19: 0.029 | J19: 0.042928571
B20: Potential | C20: Izmir | D20: 0.040357143 | E20: 0 | F20: 0.031785714 | G20: 0.023 | H20: 0.061928571 | I20: 0.072 | J20: 0.0015
C21: Sakarya | D21: 0.010571429 | E21: 0.034285714 | F21: 0.041142857 | G21: 0.011285714 | H21: 0.044571429 | I21: 0.042 | J21: 0.035785714 | L21: DEMAND:
C22: Adana | D22: 0.067071429 | E22: 0.064 | F22: 0.039714286 | G22: 0.059785714 | H22: 0.023785714 | I22: 0.054 | J22: 0.0655 | L22: Annual demand at distribution centers
C23: Samsun | D23: 0.053 | E23: 0.072 | F23: 0.064 | G23: 0.053 | H23: 0.032 | I23: 0 | J23: 0.072 | M23: Demand (million ltr)
C24: IstNew | D24: 0 | E24: 0.040357143 | F24: 0.051714286 | G24: 0.017357143 | H24: 0.055142857 | I24: 0.053 | J24: 0.041857143
C25: AnkNew | D25: 0.032357143 | E25: 0.041428571 | F25: 0.038928571 | G25: 0.027285714 | H25: 0.022785714 | I25: 0.029 | J25: 0.042928571 | L25: Dist. Centers
L26: Istanbul | M26: 150
L27: Izmir | M27: 110
B28: FIXED COSTS: | L28: Antalya | M28: 100
L29: Bursa | M29: 105
C30: (Million $) | D30: Yearly Equivalent | L30: Kayseri | M30: 140
B31: Potential Brewery Sites | D31: Open | E31: Expand | L31: Samsun | M31: 90
C32: Izmir | D32: 5 | E32: 1 | L32: Export(Izmir) | M32: 30
C33: Sakarya | D33: 4 | E33: 0.8 | L33: Total | M33: 725
C34: Adana | D34: 3.5 | E34: 0.7
C35: Samsun | D35: 2.5 | E35: 0.5
C36: IstNew | D36: 5.5 | E36: 1.2
C37: AnkNew | D37: 3.5 | E37: 0.9

Sheet Current_STS

Sheet LongTermModel
A1: Decision variables
A2: Malt shipped x(i,j) (1000 tons)
B3: From \ To | C3: Istanbul | D3: Ankara | E3: Izmir | F3: Sakarya | G3: Adana | H3: Samsun | I3: IstNew | J3: AnkNew | L3: Row sum | M3: Binary decisions
B4: Afyon | C4: 27 | D4: 3 | E4: 0 | F4: 1.0408341e-14 | G4: 0 | H4: 0 | I4: 0 | J4: 0 | L4: =SUM(C4:J4) -> 30 | M4: Site | N4: Open | O4: Expand
B5: Konya | C5: 0 | D5: 20.76 | E5: 0 | F5: 0 | G5: 1.2490009e-15 | H5: 11.4 | I5: 0 | J5: 10.8 | L5: =SUM(C5:J5) -> 42.96 | M5: Izmir | N5: 1 | O5: 1
B6: Import (Izmir) | C6: 0 | D6: 0 | E6: 14.04 | F6: 0 | G6: 0 | H6: 0 | I6: 0 | J6: 0 | L6: =SUM(C6:J6) -> 14.04 | M6: Sakarya | N6: 0 | O6: 0
M7: Adana | N7: 0 | O7: 0
M8: Samsun | N8: 1 | O8: 1
A9: Beer shipped y(j,k) (million liters) | M9: IstNew | N9: 0 | O9: 0
B10: From \ To | C10: Istanbul | D10: Izmir | E10: Antalya | F10: Bursa | G10: Kayseri | H10: Samsun | I10: Export (Izmir) | K10: Row sum | M10: AnkNew | N10: 1 | O10: 0
B11: Istanbul | C11: 150 | D11: 0 | E11: 0 | F11: 75 | G11: 0 | H11: 0 | I11: 0 | K11: =SUM(C11:I11) -> 225
B12: Ankara | C12: 0 | D12: 23 | E12: 100 | F12: 0 | G12: 75 | H12: 0 | I12: 0 | K12: =SUM(C12:I12) -> 198 | M12: CAPACITY:
B13: Izmir | C13: 0 | D13: 87 | E13: 0 | F13: 0 | G13: 0 | H13: 0 | I13: 30 | K13: =SUM(C13:I13) -> 117
B14: Sakarya | C14: 0 | D14: 0 | E14: 0 | F14: 0 | G14: 0 | H14: 0 | I14: 0 | K14: =SUM(C14:I14) -> 0 | M14: Annual capacity of malt plants
B15: Adana | C15: 0 | D15: 0 | E15: 0 | F15: 0 | G15: 0 | H15: 0 | I15: 0 | K15: =SUM(C15:I15) -> 0 | N15: (1000 tons/year)
B16: Samsun | C16: 0 | D16: 0 | E16: 0 | F16: 0 | G16: 5 | H16: 90 | I16: 0 | K16: =SUM(C16:I16) -> 95 | M16: Afyon | N16: 30
B17: IstNew | C17: 0 | D17: 0 | E17: 0 | F17: 0 | G17: 0 | H17: 0 | I17: 0 | K17: =SUM(C17:I17) -> 0 | M17: Konya | N17: 68
B18: AnkNew | C18: 0 | D18: 0 | E18: 0 | F18: 30 | G18: 60 | H18: 0 | I18: 0 | K18: =SUM(C18:I18) -> 90 | M18: Import (Izmir) | N18: 20
B20: Col sum (supply to DC) | C20: =SUM(C11:C18) -> 150 | D20: =SUM(D11:D18) -> 110 | E20: =SUM(E11:E18) -> 100 | F20: =SUM(F11:F18) -> 105 | G20: =SUM(G11:G18) -> 140 | H20: =SUM(H11:H18) -> 90 | I20: =SUM(I11:I18) -> 30
B21: Demand | C21: =LongTermData!$M$26 -> 150 | D21: =LongTermData!$M$27 -> 110 | E21: =LongTermData!$M$28 -> 100 | F21: =LongTermData!$M$29 -> 105 | G21: =LongTermData!$M$30 -> 140 | H21: =LongTermData!$M$31 -> 90 | I21: =LongTermData!$M$32 -> 30
A23: Checks
A24: Yield (million liters per 1000 tons malt) | D24: =LongTermData!$M$17 -> 8.3333333
A26: Brewery | B26: Malt in (1000 tons) | C26: Beer available (=Yield*Malt) | D26: Beer shipped (row sum) | E26: Capacity
A27: Istanbul | B27: =SUM(C4:C6) -> 27 | C27: =$D$24*B27 -> 225 | D27: =K11 -> 225 | E27: =LongTermData!$S$8*0.9 -> 225
A28: Ankara | B28: =SUM(D4:D6) -> 23.76 | C28: =$D$24*B28 -> 198 | D28: =K12 -> 198 | E28: =LongTermData!$S$9*0.9 -> 198
A29: Izmir | B29: =SUM(E4:E6) -> 14.04 | C29: =$D$24*B29 -> 117 | D29: =K13 -> 117 | E29: =(LongTermData!$S$11*N5)+(LongTermData!$T$11*O5)*0.9 -> 117
A30: Sakarya | B30: =SUM(F4:F6) -> 1.0408341e-14 | C30: =$D$24*B30 -> 8.6736174e-14 | D30: =K14 -> 0 | E30: =(LongTermData!$S$12*N6)+(LongTermData!$T$12*O6) -> 0
A31: Adana | B31: =SUM(G4:G6) -> 1.2490009e-15 | C31: =$D$24*B31 -> 1.0408341e-14 | D31: =K15 -> 0 | E31: =(LongTermData!$S$13*N7)+(LongTermData!$T$13*O7)*0.9 -> 0
A32: Samsun | B32: =SUM(H4:H6) -> 11.4 | C32: =$D$24*B32 -> 95 | D32: =K16 -> 95 | E32: =(LongTermData!$S$14*N8)+(LongTermData!$T$14*O8)*0.9 -> 117
A33: IstNew | B33: =SUM(I4:I6) -> 0 | C33: =$D$24*B33 -> 0 | D33: =K17 -> 0 | E33: =(LongTermData!$S$15*N9)+(LongTermData!$T$15*O9) -> 0
A34: AnkNew | B34: =SUM(J4:J6) -> 10.8 | C34: =$D$24*B34 -> 90 | D34: =K18 -> 90 | E34: =(LongTermData!$S$16*N10)+(LongTermData!$T$16*O10)*0.9 -> 90
A37: Objective (Minimize total cost, million $)
A38: Malt transport cost | B38: =SUMPRODUCT(C4:J6,LongTermData!$C$9:$J$11) -> 1.7257096
A39: Beer transport cost | B39: =SUMPRODUCT(C11:I18,LongTermData!$D$18:$J$25) -> 10.247143
A40: Fixed investment cost | B40: =SUMPRODUCT(N5:N10,LongTermData!D32:D37)+SUMPRODUCT(O5:O10,LongTermData!E32:E37) -> 12.5
A41: TOTAL COST | B41: =SUM(B38:B40) -> 24.472852

Sheet LongTermModel (2)
A1: Decision variables
A2: Malt shipped x(i,j) (1000 tons)
B3: From \ To | C3: Istanbul | D3: Ankara | E3: Izmir | F3: Sakarya | G3: Adana | H3: Samsun | I3: IstNew | J3: AnkNew | L3: Row sum | M3: Binary decisions
B4: Afyon | C4: 19.2 | D4: 0 | E4: 0 | F4: 10.8 | G4: 0 | H4: 0 | I4: 0 | J4: 0 | L4: =SUM(C4:J4) -> 30 | M4: Site | N4: Open | O4: Expand
B5: Konya | C5: 0 | D5: 26.4 | E5: 0 | F5: 0 | G5: 5.3290705e-15 | H5: 10.8 | I5: 0 | J5: 0 | L5: =SUM(C5:J5) -> 37.2 | M5: Izmir | N5: 1 | O5: 1
B6: Import (Izmir) | C6: 5.4 | D6: 0 | E6: 14.4 | F6: 0 | G6: 0 | H6: 0 | I6: 0 | J6: 0 | L6: =SUM(C6:J6) -> 19.8 | M6: Sakarya | N6: 1 | O6: 0
M7: Adana | N7: 0 | O7: 0
M8: Samsun | N8: 1 | O8: 0
A9: Beer shipped y(j,k) (million liters) | M9: IstNew | N9: 0 | O9: 0
B10: From \ To | C10: Istanbul | D10: Izmir | E10: Antalya | F10: Bursa | G10: Kayseri | H10: Samsun | I10: Export (Izmir) | K10: Row sum | M10: AnkNew | N10: 0 | O10: 0
B11: Istanbul | C11: 150 | D11: 20 | E11: 0 | F11: 35 | G11: 0 | H11: 0 | I11: 0 | K11: =SUM(C11:I11) -> 205
B12: Ankara | C12: 0 | D12: 0 | E12: 80 | F12: 0 | G12: 140 | H12: 0 | I12: 0 | K12: =SUM(C12:I12) -> 220 | M12: CAPACITY:
B13: Izmir | C13: 0 | D13: 90 | E13: 0 | F13: 0 | G13: 0 | H13: 0 | I13: 30 | K13: =SUM(C13:I13) -> 120
B14: Sakarya | C14: 0 | D14: 0 | E14: 20 | F14: 70 | G14: 0 | H14: 0 | I14: 0 | K14: =SUM(C14:I14) -> 90 | M14: Annual capacity of malt plants
B15: Adana | C15: 0 | D15: 0 | E15: 9.1704422e-14 | F15: 0 | G15: 0 | H15: 0 | I15: 0 | K15: =SUM(C15:I15) -> 9.1704422e-14 | N15: (1000 tons/year)
B16: Samsun | C16: 0 | D16: 0 | E16: 0 | F16: 0 | G16: 0 | H16: 90 | I16: 0 | K16: =SUM(C16:I16) -> 90 | M16: Afyon | N16: 30
B17: IstNew | C17: 0 | D17: 6.3591108e-15 | E17: 0 | F17: 0 | G17: 0 | H17: 0 | I17: 0 | K17: =SUM(C17:I17) -> 6.3591108e-15 | M17: Konya | N17: 68
B18: AnkNew | C18: 0 | D18: 0 | E18: 0 | F18: 0 | G18: 0 | H18: 0 | I18: 0 | K18: =SUM(C18:I18) -> 0 | M18: Import (Izmir) | N18: 20
B20: Col sum (supply to DC) | C20: =SUM(C11:C18) -> 150 | D20: =SUM(D11:D18) -> 110 | E20: =SUM(E11:E18) -> 100 | F20: =SUM(F11:F18) -> 105 | G20: =SUM(G11:G18) -> 140 | H20: =SUM(H11:H18) -> 90 | I20: =SUM(I11:I18) -> 30
B21: Demand | C21: =LongTermData!$M$26 -> 150 | D21: =LongTermData!$M$27 -> 110 | E21: =LongTermData!$M$28 -> 100 | F21: =LongTermData!$M$29 -> 105 | G21: =LongTermData!$M$30 -> 140 | H21: =LongTermData!$M$31 -> 90 | I21: =LongTermData!$M$32 -> 30
A23: Checks
A24: Yield (million liters per 1000 tons malt) | D24: =LongTermData!$M$17 -> 8.3333333
A26: Brewery | B26: Malt in (1000 tons) | C26: Beer available (=Yield*Malt) | D26: Beer shipped (row sum) | E26: Capacity
A27: Istanbul | B27: =SUM(C4:C6) -> 24.6 | C27: =$D$24*B27 -> 205 | D27: =K11 -> 205 | E27: =LongTermData!$S$8 -> 250
A28: Ankara | B28: =SUM(D4:D6) -> 26.4 | C28: =$D$24*B28 -> 220 | D28: =K12 -> 220 | E28: =LongTermData!$S$9 -> 220
A29: Izmir | B29: =SUM(E4:E6) -> 14.4 | C29: =$D$24*B29 -> 120 | D29: =K13 -> 120 | E29: =(LongTermData!$S$11*N5)+(LongTermData!$T$11*O5) -> 120
A30: Sakarya | B30: =SUM(F4:F6) -> 10.8 | C30: =$D$24*B30 -> 90 | D30: =K14 -> 90 | E30: =(LongTermData!$S$12*N6)+(LongTermData!$T$12*O6) -> 90
A31: Adana | B31: =SUM(G4:G6) -> 5.3290705e-15 | C31: =$D$24*B31 -> 4.4408921e-14 | D31: =K15 -> 9.1704422e-14 | E31: =(LongTermData!$S$13*N7)+(LongTermData!$T$13*O7) -> 0
A32: Samsun | B32: =SUM(H4:H6) -> 10.8 | C32: =$D$24*B32 -> 90 | D32: =K16 -> 90 | E32: =(LongTermData!$S$14*N8)+(LongTermData!$T$14*O8) -> 90
A33: IstNew | B33: =SUM(I4:I6) -> 0 | C33: =$D$24*B33 -> 0 | D33: =K17 -> 6.3591108e-15 | E33: =(LongTermData!$S$15*N9)+(LongTermData!$T$15*O9) -> 0
A34: AnkNew | B34: =SUM(J4:J6) -> 0 | C34: =$D$24*B34 -> 0 | D34: =K18 -> 0 | E34: =(LongTermData!$S$16*N10)+(LongTermData!$T$16*O10) -> 0
A37: Objective (Minimize total cost, million $)
A38: Malt transport cost | B38: =SUMPRODUCT(C4:J6,LongTermData!$C$9:$J$11) -> 1.7435633
A39: Beer transport cost | B39: =SUMPRODUCT(C11:I18,LongTermData!$D$18:$J$25) -> 9.3767857
A40: Fixed investment cost | B40: =SUMPRODUCT(N5:N10,LongTermData!D32:D37)+SUMPRODUCT(O5:O10,LongTermData!E32:E37) -> 12.5
A41: TOTAL COST | B41: =SUM(B38:B40) -> 23.620349

Sheet LongTermModel (3)
A1: Decision variables
A2: Malt shipped x(i,j) (1000 tons)
B3: From \ To | C3: Istanbul | D3: Ankara | E3: Izmir | F3: Sakarya | G3: Adana | H3: Samsun | I3: IstNew | J3: AnkNew | L3: Row sum | M3: Binary decisions
B4: Afyon | C4: 19.2 | D4: 0 | E4: 0 | F4: 10.8 | G4: 0 | H4: 0 | I4: 0 | J4: 0 | L4: =SUM(C4:J4) -> 30 | M4: Site | N4: Open | O4: Expand
B5: Konya | C5: 0 | D5: 26.4 | E5: 0 | F5: 0 | G5: 6.6613381e-15 | H5: 10.8 | I5: 0 | J5: 0 | L5: =SUM(C5:J5) -> 37.2 | M5: Izmir | N5: 1 | O5: 1
B6: Import (Izmir) | C6: 5.4 | D6: 0 | E6: 14.4 | F6: 0 | G6: 0 | H6: 0 | I6: 3.7747583e-15 | J6: 0 | L6: =SUM(C6:J6) -> 19.8 | M6: Sakarya | N6: 1 | O6: 0
M7: Adana | N7: 0 | O7: 0
M8: Samsun | N8: 1 | O8: 0
A9: Beer shipped y(j,k) (million liters) | M9: IstNew | N9: 0 | O9: 0
B10: From \ To | C10: Istanbul | D10: Izmir | E10: Antalya | F10: Bursa | G10: Kayseri | H10: Samsun | I10: Export (Izmir) | K10: Row sum | M10: AnkNew | N10: 0 | O10: 0
B11: Istanbul | C11: 150 | D11: 20 | E11: 0 | F11: 35 | G11: 0 | H11: 0 | I11: 0 | K11: =SUM(C11:I11) -> 205
B12: Ankara | C12: 0 | D12: 0 | E12: 80 | F12: 0 | G12: 140 | H12: 0 | I12: 0 | K12: =SUM(C12:I12) -> 220 | M12: CAPACITY:
B13: Izmir | C13: 0 | D13: 90 | E13: 0 | F13: 0 | G13: 0 | H13: 0 | I13: 30 | K13: =SUM(C13:I13) -> 120
B14: Sakarya | C14: 0 | D14: 0 | E14: 20 | F14: 70 | G14: 0 | H14: 0 | I14: 0 | K14: =SUM(C14:I14) -> 90 | M14: Annual capacity of malt plants
B15: Adana | C15: 0 | D15: 0 | E15: 6.3948846e-14 | F15: 0 | G15: 0 | H15: 0 | I15: 0 | K15: =SUM(C15:I15) -> 6.3948846e-14 | N15: (1000 tons/year)
B16: Samsun | C16: 0 | D16: 0 | E16: 0 | F16: 0 | G16: 0 | H16: 90 | I16: 0 | K16: =SUM(C16:I16) -> 90 | M16: Afyon | N16: 30
B17: IstNew | C17: 0 | D17: 0 | E17: 0 | F17: 0 | G17: 0 | H17: 0 | I17: 0 | K17: =SUM(C17:I17) -> 0 | M17: Konya | N17: 68
B18: AnkNew | C18: 0 | D18: 0 | E18: 0 | F18: 0 | G18: 0 | H18: 0 | I18: 0 | K18: =SUM(C18:I18) -> 0 | M18: Import (Izmir) | N18: 20
B20: Col sum (supply to DC) | C20: =SUM(C11:C18) -> 150 | D20: =SUM(D11:D18) -> 110 | E20: =SUM(E11:E18) -> 100 | F20: =SUM(F11:F18) -> 105 | G20: =SUM(G11:G18) -> 140 | H20: =SUM(H11:H18) -> 90 | I20: =SUM(I11:I18) -> 30
B21: Demand | C21: =LongTermData!$M$26 -> 150 | D21: =LongTermData!$M$27 -> 110 | E21: =LongTermData!$M$28 -> 100 | F21: =LongTermData!$M$29 -> 105 | G21: =LongTermData!$M$30 -> 140 | H21: =LongTermData!$M$31 -> 90 | I21: =LongTermData!$M$32 -> 30
A23: Checks
A24: Yield (million liters per 1000 tons malt) | D24: =LongTermData!$M$17 -> 8.3333333
A26: Brewery | B26: Malt in (1000 tons) | C26: Beer available (=Yield*Malt) | D26: Beer shipped (row sum) | E26: Capacity
A27: Istanbul | B27: =SUM(C4:C6) -> 24.6 | C27: =$D$24*B27 -> 205 | D27: =K11 -> 205 | E27: =LongTermData!$S$8 -> 250
A28: Ankara | B28: =SUM(D4:D6) -> 26.4 | C28: =$D$24*B28 -> 220 | D28: =K12 -> 220 | E28: =LongTermData!$S$9 -> 220
A29: Izmir | B29: =SUM(E4:E6) -> 14.4 | C29: =$D$24*B29 -> 120 | D29: =K13 -> 120 | E29: =(LongTermData!$S$11*N5)+(LongTermData!$T$11*O5) -> 120
A30: Sakarya | B30: =SUM(F4:F6) -> 10.8 | C30: =$D$24*B30 -> 90 | D30: =K14 -> 90 | E30: =(LongTermData!$S$12*N6)+(LongTermData!$T$12*O6) -> 90
A31: Adana | B31: =SUM(G4:G6) -> 6.6613381e-15 | C31: =$D$24*B31 -> 5.5511151e-14 | D31: =K15 -> 6.3948846e-14 | E31: =(LongTermData!$S$13*N7)+(LongTermData!$T$13*O7) -> 0
A32: Samsun | B32: =SUM(H4:H6) -> 10.8 | C32: =$D$24*B32 -> 90 | D32: =K16 -> 90 | E32: =(LongTermData!$S$14*N8)+(LongTermData!$T$14*O8) -> 90
A33: IstNew | B33: =SUM(I4:I6) -> 3.7747583e-15 | C33: =$D$24*B33 -> 3.1456319e-14 | D33: =K17 -> 0 | E33: =(LongTermData!$S$15*N9)+(LongTermData!$T$15*O9) -> 0
A34: AnkNew | B34: =SUM(J4:J6) -> 0 | C34: =$D$24*B34 -> 0 | D34: =K18 -> 0 | E34: =(LongTermData!$S$16*N10)+(LongTermData!$T$16*O10) -> 0
A37: Objective (Minimize total cost, million $)
A38: Malt transport cost | B38: =SUMPRODUCT(C4:J6,LongTermData!$C$9:$J$11) -> 1.7435633
A39: Beer transport cost | B39: =SUMPRODUCT(C11:I18,LongTermData!$D$18:$J$25) -> 9.3767857
A40: Fixed investment cost | B40: =SUMPRODUCT(N5:N10,LongTermData!D32:D37)+SUMPRODUCT(O5:O10,LongTermData!E32:E37) -> 12.5
A41: TOTAL COST | B41: =SUM(B38:B40) -> 23.620349

Sheet LongTermModel (4)
A1: Decision variables
A2: Malt shipped x(i,j) (1000 tons)
B3: From \ To | C3: Istanbul | D3: Ankara | E3: Izmir | F3: Sakarya | G3: Adana | H3: Samsun | I3: IstNew | J3: AnkNew | L3: Row sum | M3: Binary decisions
B4: Afyon | C4: 30 | D4: 0 | E4: 0 | F4: 0 | G4: 0 | H4: 0 | I4: 0 | J4: 0 | L4: =SUM(C4:J4) -> 30 | M4: Site | N4: Open | O4: Expand
B5: Konya | C5: 0 | D5: 26.4 | E5: 0 | F5: 0 | G5: 0 | H5: 10.8 | I5: 0 | J5: 9 | L5: =SUM(C5:J5) -> 46.2 | M5: Izmir | N5: 1 | O5: 0
B6: Import (Izmir) | C6: 0 | D6: 0 | E6: 10.8 | F6: 0 | G6: 0 | H6: 0 | I6: 0 | J6: 0 | L6: =SUM(C6:J6) -> 10.8 | M6: Sakarya | N6: 0 | O6: 0
M7: Adana | N7: 0 | O7: 0
M8: Samsun | N8: 1 | O8: 0
A9: Beer shipped y(j,k) (million liters) | M9: IstNew | N9: 0 | O9: 0
B10: From \ To | C10: Istanbul | D10: Izmir | E10: Antalya | F10: Bursa | G10: Kayseri | H10: Samsun | I10: Export (Izmir) | K10: Row sum | M10: AnkNew | N10: 1 | O10: 0
B11: Istanbul | C11: 150 | D11: 0 | E11: 0 | F11: 100 | G11: 0 | H11: 0 | I11: 0 | K11: =SUM(C11:I11) -> 250
B12: Ankara | C12: 0 | D12: 0 | E12: 100 | F12: 0 | G12: 120 | H12: 0 | I12: 0 | K12: =SUM(C12:I12) -> 220 | M12: CAPACITY:
B13: Izmir | C13: 0 | D13: 60 | E13: 0 | F13: 0 | G13: 0 | H13: 0 | I13: 30 | K13: =SUM(C13:I13) -> 90
B14: Sakarya | C14: 0 | D14: 0 | E14: 0 | F14: 0 | G14: 0 | H14: 0 | I14: 0 | K14: =SUM(C14:I14) -> 0 | M14: Annual capacity of malt plants
B15: Adana | C15: 0 | D15: 0 | E15: 0 | F15: 0 | G15: 0 | H15: 0 | I15: 0 | K15: =SUM(C15:I15) -> 0 | N15: (1000 tons/year)
B16: Samsun | C16: 0 | D16: 0 | E16: 0 | F16: 0 | G16: 0 | H16: 90 | I16: 0 | K16: =SUM(C16:I16) -> 90 | M16: Afyon | N16: 30
B17: IstNew | C17: 0 | D17: 0 | E17: 0 | F17: 0 | G17: 0 | H17: 0 | I17: 0 | K17: =SUM(C17:I17) -> 0 | M17: Konya | N17: 68
B18: AnkNew | C18: 0 | D18: 50 | E18: 0 | F18: 5 | G18: 20 | H18: 0 | I18: 0 | K18: =SUM(C18:I18) -> 75 | M18: Import (Izmir) | N18: 20
B20: Col sum (supply to DC) | C20: =SUM(C11:C18) -> 150 | D20: =SUM(D11:D18) -> 110 | E20: =SUM(E11:E18) -> 100 | F20: =SUM(F11:F18) -> 105 | G20: =SUM(G11:G18) -> 140 | H20: =SUM(H11:H18) -> 90 | I20: =SUM(I11:I18) -> 30
B21: Demand | C21: =LongTermData!$M$26 -> 150 | D21: =LongTermData!$M$27 -> 110 | E21: =LongTermData!$M$28 -> 100 | F21: =LongTermData!$M$29 -> 105 | G21: =LongTermData!$M$30 -> 140 | H21: =LongTermData!$M$31 -> 90 | I21: =LongTermData!$M$32 -> 30
A23: Checks
A24: Yield (million liters per 1000 tons malt) | D24: =LongTermData!$M$17 -> 8.3333333
A26: Brewery | B26: Malt in (1000 tons) | C26: Beer available (=Yield*Malt) | D26: Beer shipped (row sum) | E26: Capacity
A27: Istanbul | B27: =SUM(C4:C6) -> 30 | C27: =$D$24*B27 -> 250 | D27: =K11 -> 250 | E27: =LongTermData!$S$8 -> 250
A28: Ankara | B28: =SUM(D4:D6) -> 26.4 | C28: =$D$24*B28 -> 220 | D28: =K12 -> 220 | E28: =LongTermData!$S$9 -> 220
A29: Izmir | B29: =SUM(E4:E6) -> 10.8 | C29: =$D$24*B29 -> 90 | D29: =K13 -> 90 | E29: =(LongTermData!$S$11*N5)+(LongTermData!$T$11*O5) -> 90
A30: Sakarya | B30: =SUM(F4:F6) -> 0 | C30: =$D$24*B30 -> 0 | D30: =K14 -> 0 | E30: =(LongTermData!$S$12*N6)+(LongTermData!$T$12*O6) -> 0
A31: Adana | B31: =SUM(G4:G6) -> 0 | C31: =$D$24*B31 -> 0 | D31: =K15 -> 0 | E31: =(LongTermData!$S$13*N7)+(LongTermData!$T$13*O7) -> 0
A32: Samsun | B32: =SUM(H4:H6) -> 10.8 | C32: =$D$24*B32 -> 90 | D32: =K16 -> 90 | E32: =(LongTermData!$S$14*N8)+(LongTermData!$T$14*O8) -> 90
A33: IstNew | B33: =SUM(I4:I6) -> 0 | C33: =$D$24*B33 -> 0 | D33: =K17 -> 0 | E33: =(LongTermData!$S$15*N9)+(LongTermData!$T$15*O9) -> 0
A34: AnkNew | B34: =SUM(J4:J6) -> 9 | C34: =$D$24*B34 -> 75 | D34: =K18 -> 75 | E34: =(LongTermData!$S$16*N10)+(LongTermData!$T$16*O10) -> 90
A37: Objective (Minimize total cost, million $)
A38: Malt transport cost | B38: =SUMPRODUCT(C4:J6,LongTermData!$C$9:$J$11) -> 1.7861639
A39: Beer transport cost | B39: =SUMPRODUCT(C11:I18,LongTermData!$D$18:$J$25) -> 11.071429
A40: Fixed investment cost | B40: =SUMPRODUCT(N5:N10,LongTermData!D32:D37)+SUMPRODUCT(O5:O10,LongTermData!E32:E37) -> 11
A41: TOTAL COST | B41: =SUM(B38:B40) -> 23.857592

Sheet LongTermModel (5)
A1: Decision variables
A2: Malt shipped x(i,j) (1000 tons)
B3: From \ To | C3: Istanbul | D3: Ankara | E3: Izmir | F3: Sakarya | G3: Adana | H3: Samsun | I3: IstNew | J3: AnkNew | L3: Row sum | M3: Binary decisions
B4: Afyon | C4: 30 | D4: 0 | E4: 0 | F4: 0 | G4: 0 | H4: 0 | I4: 0 | J4: 0 | L4: =SUM(C4:J4) -> 30 | M4: Site | N4: Open | O4: Expand
B5: Konya | C5: 0 | D5: 26.4 | E5: 0 | F5: 0 | G5: 0 | H5: 10.8 | I5: 0 | J5: 5.4 | L5: =SUM(C5:J5) -> 42.6 | M5: Izmir | N5: 1 | O5: 1
B6: Import (Izmir) | C6: 3.1918912e-15 | D6: 0 | E6: 14.4 | F6: 0 | G6: 0 | H6: 0 | I6: 0 | J6: 0 | L6: =SUM(C6:J6) -> 14.4 | M6: Sakarya | N6: 0 | O6: 0
M7: Adana | N7: 0 | O7: 0
M8: Samsun | N8: 1 | O8: 0
A9: Beer shipped y(j,k) (million liters) | M9: IstNew | N9: 0 | O9: 0
B10: From \ To | C10: Istanbul | D10: Izmir | E10: Antalya | F10: Bursa | G10: Kayseri | H10: Samsun | I10: Export (Izmir) | K10: Row sum | M10: AnkNew | N10: 1 | O10: 0
B11: Istanbul | C11: 150 | D11: 0 | E11: 0 | F11: 100 | G11: 0 | H11: 0 | I11: 0 | K11: =SUM(C11:I11) -> 250
B12: Ankara | C12: 0 | D12: 20 | E12: 60 | F12: 0 | G12: 140 | H12: 0 | I12: 0 | K12: =SUM(C12:I12) -> 220 | M12: CAPACITY:
B13: Izmir | C13: 0 | D13: 90 | E13: 0 | F13: 0 | G13: 0 | H13: 0 | I13: 30 | K13: =SUM(C13:I13) -> 120
B14: Sakarya | C14: 0 | D14: 0 | E14: 0 | F14: 4.2188475e-15 | G14: 0 | H14: 0 | I14: 0 | K14: =SUM(C14:I14) -> 4.2188475e-15 | M14: Annual capacity of malt plants
B15: Adana | C15: 0 | D15: 0 | E15: 0 | F15: 0 | G15: 0 | H15: 0 | I15: 0 | K15: =SUM(C15:I15) -> 0 | N15: (1000 tons/year)
B16: Samsun | C16: 0 | D16: 0 | E16: 0 | F16: 0 | G16: 0 | H16: 90 | I16: 0 | K16: =SUM(C16:I16) -> 90 | M16: Afyon | N16: 30
B17: IstNew | C17: 0 | D17: 0 | E17: 0 | F17: 1.8429702e-14 | G17: 0 | H17: 0 | I17: 0 | K17: =SUM(C17:I17) -> 1.8429702e-14 | M17: Konya | N17: 68
B18: AnkNew | C18: 0 | D18: 0 | E18: 40 | F18: 5 | G18: 0 | H18: 0 | I18: 0 | K18: =SUM(C18:I18) -> 45 | M18: Import (Izmir) | N18: 20
B20: Col sum (supply to DC) | C20: =SUM(C11:C18) -> 150 | D20: =SUM(D11:D18) -> 110 | E20: =SUM(E11:E18) -> 100 | F20: =SUM(F11:F18) -> 105 | G20: =SUM(G11:G18) -> 140 | H20: =SUM(H11:H18) -> 90 | I20: =SUM(I11:I18) -> 30
B21: Demand | C21: =LongTermData!$M$26 -> 150 | D21: =LongTermData!$M$27 -> 110 | E21: =LongTermData!$M$28 -> 100 | F21: =LongTermData!$M$29 -> 105 | G21: =LongTermData!$M$30 -> 140 | H21: =LongTermData!$M$31 -> 90 | I21: =LongTermData!$M$32 -> 30
A23: Checks
A24: Yield (million liters per 1000 tons malt) | D24: =LongTermData!$M$17 -> 8.3333333
A26: Brewery | B26: Malt in (1000 tons) | C26: Beer available (=Yield*Malt) | D26: Beer shipped (row sum) | E26: Capacity
A27: Istanbul | B27: =SUM(C4:C6) -> 30 | C27: =$D$24*B27 -> 250 | D27: =K11 -> 250 | E27: =LongTermData!$S$8 -> 250
A28: Ankara | B28: =SUM(D4:D6) -> 26.4 | C28: =$D$24*B28 -> 220 | D28: =K12 -> 220 | E28: =LongTermData!$S$9 -> 220
A29: Izmir | B29: =SUM(E4:E6) -> 14.4 | C29: =$D$24*B29 -> 120 | D29: =K13 -> 120 | E29: =(LongTermData!$S$11*N5)+(LongTermData!$T$11*O5) -> 120
A30: Sakarya | B30: =SUM(F4:F6) -> 0 | C30: =$D$24*B30 -> 0 | D30: =K14 -> 4.2188475e-15 | E30: =(LongTermData!$S$12*N6)+(LongTermData!$T$12*O6) -> 0
A31: Adana | B31: =SUM(G4:G6) -> 0 | C31: =$D$24*B31 -> 0 | D31: =K15 -> 0 | E31: =(LongTermData!$S$13*N7)+(LongTermData!$T$13*O7) -> 0
A32: Samsun | B32: =SUM(H4:H6) -> 10.8 | C32: =$D$24*B32 -> 90 | D32: =K16 -> 90 | E32: =(LongTermData!$S$14*N8)+(LongTermData!$T$14*O8) -> 90
A33: IstNew | B33: =SUM(I4:I6) -> 0 | C33: =$D$24*B33 -> 0 | D33: =K17 -> 1.8429702e-14 | E33: =(LongTermData!$S$15*N9)+(LongTermData!$T$15*O9) -> 0
A34: AnkNew | B34: =SUM(J4:J6) -> 5.4 | C34: =$D$24*B34 -> 45 | D34: =K18 -> 45 | E34: =(LongTermData!$S$16*N10)+(LongTermData!$T$16*O10) -> 90
A37: Objective (Minimize total cost, million $)
A38: Malt transport cost | B38: =SUMPRODUCT(C4:J6,LongTermData!$C$9:$J$11) -> 1.7406527
A39: Beer transport cost | B39: =SUMPRODUCT(C11:I18,LongTermData!$D$18:$J$25) -> 9.8285714
A40: Fixed investment cost | B40: =SUMPRODUCT(N5:N10,LongTermData!D32:D37)+SUMPRODUCT(O5:O10,LongTermData!E32:E37) -> 12
A41: TOTAL COST | B41: =SUM(B38:B40) -> 23.569224

Sheet LongTermModel (6)
A1: Decision variables
A2: Malt shipped x(i,j) (1000 tons)
B3: From \ To | C3: Istanbul | D3: Ankara | E3: Izmir | F3: Sakarya | G3: Adana | H3: Samsun | I3: IstNew | J3: AnkNew | L3: Row sum | M3: Binary decisions
B4: Afyon | C4: 19.2 | D4: 0 | E4: 0 | F4: 10.8 | G4: 0 | H4: 0 | I4: 2.4842628e-13 | J4: 0 | L4: =SUM(C4:J4) -> 30 | M4: Site | N4: Open | O4: Expand
B5: Konya | C5: 0 | D5: 26.4 | E5: 0 | F5: 0 | G5: 0 | H5: 0 | I5: 0 | J5: 10.8 | L5: =SUM(C5:J5) -> 37.2 | M5: Izmir | N5: 1 | O5: 1
B6: Import (Izmir) | C6: 5.4 | D6: 0 | E6: 14.4 | F6: 0 | G6: 0 | H6: 0 | I6: 0 | J6: 0 | L6: =SUM(C6:J6) -> 19.8 | M6: Sakarya | N6: 1 | O6: 0
M7: Adana | N7: 0 | O7: 0
M8: Samsun | N8: 0 | O8: 0
A9: Beer shipped y(j,k) (million liters) | M9: IstNew | N9: 0 | O9: 0
B10: From \ To | C10: Istanbul | D10: Izmir | E10: Antalya | F10: Bursa | G10: Kayseri | H10: Samsun | I10: Export (Izmir) | K10: Row sum | M10: AnkNew | N10: 1 | O10: 0
B11: Istanbul | C11: 150 | D11: 20 | E11: 0 | F11: 35 | G11: 0 | H11: 0 | I11: 0 | K11: =SUM(C11:I11) -> 205
B12: Ankara | C12: 0 | D12: 0 | E12: 80 | F12: 0 | G12: 140 | H12: 4.5297099e-14 | I12: 0 | K12: =SUM(C12:I12) -> 220 | M12: CAPACITY:
B13: Izmir | C13: 0 | D13: 90 | E13: 0 | F13: 0 | G13: 0 | H13: 0 | I13: 30 | K13: =SUM(C13:I13) -> 120
B14: Sakarya | C14: 0 | D14: 0 | E14: 20 | F14: 70 | G14: 0 | H14: 0 | I14: 0 | K14: =SUM(C14:I14) -> 90 | M14: Annual capacity of malt plants
B15: Adana | C15: 0 | D15: 0 | E15: 0 | F15: 0 | G15: 0 | H15: 0 | I15: 0 | K15: =SUM(C15:I15) -> 0 | N15: (1000 tons/year)
B16: Samsun | C16: 0 | D16: 0 | E16: 0 | F16: 0 | G16: 0 | H16: 0 | I16: 0 | K16: =SUM(C16:I16) -> 0 | M16: Afyon | N16: 30
B17: IstNew | C17: 0 | D17: 0 | E17: 0 | F17: 2.083204e-12 | G17: 0 | H17: 0 | I17: 0 | K17: =SUM(C17:I17) -> 2.083204e-12 | M17: Konya | N17: 68
B18: AnkNew | C18: 0 | D18: 0 | E18: 0 | F18: 0 | G18: 0 | H18: 90 | I18: 0 | K18: =SUM(C18:I18) -> 90 | M18: Import (Izmir) | N18: 20
B20: Col sum (supply to DC) | C20: =SUM(C11:C18) -> 150 | D20: =SUM(D11:D18) -> 110 | E20: =SUM(E11:E18) -> 100 | F20: =SUM(F11:F18) -> 105 | G20: =SUM(G11:G18) -> 140 | H20: =SUM(H11:H18) -> 90 | I20: =SUM(I11:I18) -> 30
B21: Demand | C21: =LongTermData!$M$26 -> 150 | D21: =LongTermData!$M$27 -> 110 | E21: =LongTermData!$M$28 -> 100 | F21: =LongTermData!$M$29 -> 105 | G21: =LongTermData!$M$30 -> 140 | H21: =LongTermData!$M$31 -> 90 | I21: =LongTermData!$M$32 -> 30
A23: Checks
A24: Yield (million liters per 1000 tons malt) | D24: =LongTermData!$M$17 -> 8.3333333
A26: Brewery | B26: Malt in (1000 tons) | C26: Beer available (=Yield*Malt) | D26: Beer shipped (row sum) | E26: Capacity
A27: Istanbul | B27: =SUM(C4:C6) -> 24.6 | C27: =$D$24*B27 -> 205 | D27: =K11 -> 205 | E27: =LongTermData!$S$8 -> 250
A28: Ankara | B28: =SUM(D4:D6) -> 26.4 | C28: =$D$24*B28 -> 220 | D28: =K12 -> 220 | E28: =LongTermData!$S$9 -> 220
A29: Izmir | B29: =SUM(E4:E6) -> 14.4 | C29: =$D$24*B29 -> 120 | D29: =K13 -> 120 | E29: =(LongTermData!$S$11*N5)+(LongTermData!$T$11*O5) -> 120
A30: Sakarya | B30: =SUM(F4:F6) -> 10.8 | C30: =$D$24*B30 -> 90 | D30: =K14 -> 90 | E30: =(LongTermData!$S$12*N6)+(LongTermData!$T$12*O6) -> 90
A31: Adana | B31: =SUM(G4:G6) -> 0 | C31: =$D$24*B31 -> 0 | D31: =K15 -> 0 | E31: =(LongTermData!$S$13*N7)+(LongTermData!$T$13*O7) -> 0
A32: Samsun | B32: =SUM(H4:H6) -> 0 | C32: =$D$24*B32 -> 0 | D32: =K16 -> 0 | E32: =(LongTermData!$S$14*N8)+(LongTermData!$T$14*O8) -> 0
A33: IstNew | B33: =SUM(I4:I6) -> 2.4842628e-13 | C33: =$D$24*B33 -> 2.070219e-12 | D33: =K17 -> 2.083204e-12 | E33: =(LongTermData!$S$15*N9)+(LongTermData!$T$15*O9) -> 0
A34: AnkNew | B34: =SUM(J4:J6) -> 10.8 | C34: =$D$24*B34 -> 90 | D34: =K18 -> 90 | E34: =(LongTermData!$S$16*N10)+(LongTermData!$T$16*O10) -> 90
A37: Objective (Minimize total cost, million $)
A38: Malt transport cost | B38: =SUMPRODUCT(C4:J6,LongTermData!$C$9:$J$11) -> 1.5679056
A39: Beer transport cost | B39: =SUMPRODUCT(C11:I18,LongTermData!$D$18:$J$25) -> 11.986786
A40: Fixed investment cost | B40: =SUMPRODUCT(N5:N10,LongTermData!D32:D37)+SUMPRODUCT(O5:O10,LongTermData!E32:E37) -> 13.5
A41: TOTAL COST | B41: =SUM(B38:B40) -> 27.054691

Sheet LongTermModel (7)
A1: Decision variables
A2: Malt shipped x(i,j) (1000 tons)
B3: From \ To | C3: Istanbul | D3: Ankara | E3: Izmir | F3: Sakarya | G3: Adana | H3: Samsun | I3: IstNew | J3: AnkNew | L3: Row sum | M3: Binary decisions
B4: Afyon | C4: 19.2 | D4: 0 | E4: 0 | F4: 10.8 | G4: 0 | H4: 0 | I4: 7.4838284e-14 | J4: 0 | L4: =SUM(C4:J4) -> 30 | M4: Site | N4: Open | O4: Expand
B5: Konya | C5: 0 | D5: 26.4 | E5: 0 | F5: 0 | G5: 10.8 | H5: 0 | I5: 0 | J5: 0 | L5: =SUM(C5:J5) -> 37.2 | M5: Izmir | N5: 1 | O5: 1
B6: Import (Izmir) | C6: 5.4 | D6: 0 | E6: 14.4 | F6: 0 | G6: 0 | H6: 0 | I6: 0 | J6: 0 | L6: =SUM(C6:J6) -> 19.8 | M6: Sakarya | N6: 1 | O6: 0
M7: Adana | N7: 1 | O7: 0
M8: Samsun | N8: 0 | O8: 0
A9: Beer shipped y(j,k) (million liters) | M9: IstNew | N9: 0 | O9: 0
B10: From \ To | C10: Istanbul | D10: Izmir | E10: Antalya | F10: Bursa | G10: Kayseri | H10: Samsun | I10: Export (Izmir) | K10: Row sum | M10: AnkNew | N10: 0 | O10: 0
B11: Istanbul | C11: 150 | D11: 20 | E11: 0 | F11: 35 | G11: 0 | H11: 0 | I11: 0 | K11: =SUM(C11:I11) -> 205
B12: Ankara | C12: 0 | D12: 0 | E12: 0 | F12: 0 | G12: 130 | H12: 90 | I12: 0 | K12: =SUM(C12:I12) -> 220 | M12: CAPACITY:
B13: Izmir | C13: 0 | D13: 90 | E13: 0 | F13: 0 | G13: 0 | H13: 0 | I13: 30 | K13: =SUM(C13:I13) -> 120
B14: Sakarya | C14: 0 | D14: 0 | E14: 20 | F14: 70 | G14: 0 | H14: 0 | I14: 0 | K14: =SUM(C14:I14) -> 90 | M14: Annual capacity of malt plants
B15: Adana | C15: 0 | D15: 0 | E15: 80 | F15: 0 | G15: 10 | H15: 0 | I15: 0 | K15: =SUM(C15:I15) -> 90 | N15: (1000 tons/year)
B16: Samsun | C16: 0 | D16: 0 | E16: 0 | F16: 0 | G16: 0 | H16: 0 | I16: 0 | K16: =SUM(C16:I16) -> 0 | M16: Afyon | N16: 30
B17: IstNew | C17: 0 | D17: 0 | E17: 0 | F17: 6.212808e-13 | G17: 0 | H17: 0 | I17: 0 | K17: =SUM(C17:I17) -> 6.212808e-13 | M17: Konya | N17: 68
B18: AnkNew | C18: 0 | D18: 0 | E18: 0 | F18: 0 | G18: 0 | H18: 0 | I18: 0 | K18: =SUM(C18:I18) -> 0 | M18: Import (Izmir) | N18: 20
B20: Col sum (supply to DC) | C20: =SUM(C11:C18) -> 150 | D20: =SUM(D11:D18) -> 110 | E20: =SUM(E11:E18) -> 100 | F20: =SUM(F11:F18) -> 105 | G20: =SUM(G11:G18) -> 140 | H20: =SUM(H11:H18) -> 90 | I20: =SUM(I11:I18) -> 30
B21: Demand | C21: =LongTermData!$M$26 -> 150 | D21: =LongTermData!$M$27 -> 110 | E21: =LongTermData!$M$28 -> 100 | F21: =LongTermData!$M$29 -> 105 | G21: =LongTermData!$M$30 -> 140 | H21: =LongTermData!$M$31 -> 90 | I21: =LongTermData!$M$32 -> 30
A23: Checks
A24: Yield (million liters per 1000 tons malt) | D24: =LongTermData!$M$17 -> 8.3333333
A26: Brewery | B26: Malt in (1000 tons) | C26: Beer available (=Yield*Malt) | D26: Beer shipped (row sum) | E26: Capacity
A27: Istanbul | B27: =SUM(C4:C6) -> 24.6 | C27: =$D$24*B27 -> 205 | D27: =K11 -> 205 | E27: =LongTermData!$S$8 -> 250
A28: Ankara | B28: =SUM(D4:D6) -> 26.4 | C28: =$D$24*B28 -> 220 | D28: =K12 -> 220 | E28: =LongTermData!$S$9 -> 220
A29: Izmir | B29: =SUM(E4:E6) -> 14.4 | C29: =$D$24*B29 -> 120 | D29: =K13 -> 120 | E29: =(LongTermData!$S$11*N5)+(LongTermData!$T$11*O5) -> 120
A30: Sakarya | B30: =SUM(F4:F6) -> 10.8 | C30: =$D$24*B30 -> 90 | D30: =K14 -> 90 | E30: =(LongTermData!$S$12*N6)+(LongTermData!$T$12*O6) -> 90
A31: Adana | B31: =SUM(G4:G6) -> 10.8 | C31: =$D$24*B31 -> 90 | D31: =K15 -> 90 | E31: =(LongTermData!$S$13*N7)+(LongTermData!$T$13*O7) -> 90
A32: Samsun | B32: =SUM(H4:H6) -> 0 | C32: =$D$24*B32 -> 0 | D32: =K16 -> 0 | E32: =(LongTermData!$S$14*N8)+(LongTermData!$T$14*O8) -> 0
A33: IstNew | B33: =SUM(I4:I6) -> 7.4838284e-14 | C33: =$D$24*B33 -> 6.2365236e-13 | D33: =K17 -> 6.212808e-13 | E33: =(LongTermData!$S$15*N9)+(LongTermData!$T$15*O9) -> 0
A34: AnkNew | B34: =SUM(J4:J6) -> 0 | C34: =$D$24*B34 -> 0 | D34: =K18 -> 0 | E34: =(LongTermData!$S$16*N10)+(LongTermData!$T$16*O10) -> 0
A37: Objective (Minimize total cost, million $)
A38: Malt transport cost | B38: =SUMPRODUCT(C4:J6,LongTermData!$C$9:$J$11) -> 1.6197672
A39: Beer transport cost | B39: =SUMPRODUCT(C11:I18,LongTermData!$D$18:$J$25) -> 12.059643
A40: Fixed investment cost | B40: =SUMPRODUCT(N5:N10,LongTermData!D32:D37)+SUMPRODUCT(O5:O10,LongTermData!E32:E37) -> 13.5
A41: TOTAL COST | B41: =SUM(B38:B40) -> 27.17941

Sheet LongTermModel_STS
